Workbook

Sheet MS_IT.2026
A1: BITEXCO PROPERTY
B2: Tầm nhìn Bitexco/Bitexco Vision | C2: Bitexco Group's goal is to be a leading international, multi-industry corporation. We aim to be globally competitive by executing world-class projects, thus making a significant contribution to the economic development and future of Vietnam./Mục tiêu của Tập đoàn Bitexco là trở thành một tập đoàn quốc tế, đa ngành hàng đầu. Chúng tôi đặt mục tiêu cạnh tranh toàn cầu bằng cách thực hiện các dự án đẳng cấp thế giới, đóng góp vào sự phát triển kinh tế và tương lai của Việt Nam.
B3: Department Vision/Tầm nhìn Bộ phận | C3: Ban Công nghệ Thông tin Bitexco định hướng trở thành động lực chiến lược trong hành trình chuyển đổi Công ty bất động sản truyền thống của Bitexco thành Công ty Công nghệ Bất động sản (PropTech), thông qua việc xây dựng và vận hành nền tảng công nghệ và dữ liệu hiện đại, an toàn, linh hoạt, làm nền tảng cho quản lý, vận hành và đầu tư tài sản hiệu quả, minh bạch và bền vững, góp phần nâng cao năng lực cạnh tranh và giá trị dài hạn của Bitexco. The Information Technology Division of Bitexco is positioned to become a strategic driving force in transforming Bitexco from a traditional real estate company into a Real Estate Technology (PropTech) company, by building and operating modern, secure, and flexible technology and data platforms that serve as the foundation for efficient, transparent, and sustainable asset management, operations, and investment, thereby enhancing Bitexco’s competitiveness and long-term value.
B4: Sứ mệnh Bitexco/Bitexco Mission | C4: Bitexco Group has always played a pioneering role in the key areas of the Vietnamese economy. We always strive to develop and introduce international standards into every our project. Our staff & the member companies in the Group always strive to achieve the highest standards. Contributing to Vietnam's economic development and improving people's quality of life is at the heart of our business philosophy. As an international corporation, Bitexco Group is responsible for contributing to the national interests and promoting the image of a dynamic and prosperous Vietnam around the world. In increasingly modernized world nowadays, Bitexco Group's top priority is solid economic development both at home and abroad. /Tập đoàn Bitexco luôn đóng vai trò tiên phong trong các lĩnh vực then chốt của nền kinh tế Việt Nam. Chúng tôi luôn nỗ lực phấn đấu phát triển và đưa các tiêu chuẩn quốc tế vào từng dự án chúng tôi thực hiện. Đội ngũ cán bộ nhân viên cũng như các công ty thành viên trong Tập đoàn luôn không ngừng phấn đấu đạt tới chuẩn mực cao nhất. Góp phần vào quá trình phát triển kinh tế Việt Nam và nâng cao chất lượng sống cho người dân là trọng tâm của triết lý kinh doanh của chúng tôi. Với vai trò là một Tập đoàn mang tầm vóc quốc tế, Tập đoàn Bitexco có trách nhiệm đóng góp vào lợi ích quốc gia và quảng bá hình ảnh về một đất nước Việt Nam năng động và thịnh vượng trên toàn thế giới. Trong một thế giới hiện đại hoá ngày càng sâu rộng như hiện nay, ưu tiên trọng tâm hàng đầu của Tập đoàn chúng tôi là phát triển kinh tế bền vững ở cả trong và ngoài nước.
B5: Sứ mệnh Bộ phận/Department Mission | C5: Ban Công nghệ Thông tin Bitexco có sứ mệnh dẫn dắt và đồng hành cùng Tập đoàn chuyển dịch từ mô hình phát triển bất động sản truyền thống sang mô hình quản lý, đầu tư và vận hành tài sản dựa trên công nghệ và dữ liệu, coi dữ liệu là tài sản chiến lược, từng bước xây dựng Bitexco trở thành Doanh nghiệp Công nghệ Bất động sản (PropTech), nâng cao hiệu quả vận hành, đầu tư và năng lực cạnh tranh dài hạn. The Information Technology Division of Bitexco leads and supports the Group’s transition to a technology- and data-driven asset management, investment, and operations model, treating data as a strategic asset and progressively transforming Bitexco into a Real Estate Technology (PropTech) enterprise to enhance operational efficiency and long-term competitiveness.
B6: Chiến lược của Bitexco Property/ Strategy of Bitexco Property | C6: Công ty Công nghệ Bất động sản/Property Technology Company (PropTech Company)
E7: Vai trò phối hợp của các bộ phận trong Property/Coordinating roles of functional departments in Property: R - Thực hiện chính/Main Responsible; S - Hỗ trợ thực hiện/Support; C - Bên tham vấn/Consult, I - Bên nhận thông tin/Informed, A - Phê duyệt kết quả/Approve | I7: Property internal personnel' roles: R - Thực hiện chính/Main Responsible; S - Hỗ trợ thực hiện/Support; C - Bên tham vấn/Consult, A - Chịu trách nhiệm kết quả của bộ phận/Accountable for department's results
E8: R, S, C, I: Có thể liên quan nhiều bộ phận trên mỗi dòng công việc/ May involve multiple departments each line; A: chỉ điền 1 bộ phận trên mỗi dòng công việc/ Only fill one department is ultimately accountable for each line | I8: R, S, C: Có thể liên quan nhiều người trên mỗi dòng công việc/ May involve multiple individuals each line; A: chỉ điền 1 người trên mỗi dòng công việc/ Only fill one individual is ultimately accountable for each line
A9: Stt/ No | B9: Phân nhóm chức năng của Bộ phận/ Functional grouping of Department | C9: Mục tiêu của Bộ phận/ Objectives of Department | D9: Kết quả chính cần đạt được trong năm 2026 của Bộ phận 2026 Key Deliverables of Department | E9: BOD Property | F9: Tên các Công ty, Dự án cần phụ trách Names of companies, projects to be in charge of | G9: Tên đối tác thuê ngoài cụ thể/loại hình đối tác thuê ngoài Name of specific outsourced partners / type of outsourced partners | H9: Ngân sách thuê ngoài Outsourcing Budget (tỷ đồng/billion dong) | I9: PHẠM THỊ MAI | J9: NGUYỄN VĂN THÀNH | K9: LÊ QUANG HUY | L9: NGUYỄN NHƯ THÀNH | M9: VŨ VĂN LONG | N9: NGUYỄN THÀNH LÂM | O9: GARDEN-SW | P9: TẠ THÀNH ĐƯC | Q9: LÀM THANH HOÀNG | R9: NGÔ TRỌNG KHOA | S9: IT - MINH QUANG | T9: IT - BHMC
A10: I | B10: XÂY DỰNG CHIẾN LƯỢC/STRATEGY DEVELOPMENT | F10: BITEXCO PROPERTY: BITEXCO JSC VP, BFT, TMCP THE GARDEN, AURA/BHMC, MINH QUANG, BIGNANOTECH, BIGCAPTAL, OV, KLOES/DW, BTC&BIG ENERGY, THEMANOR/BMTL/PMG, THESTARFITNESS, DADAY/BT-CHUVANAN, Diamond | G10: FPT Digital, CMC solution, EY-Parthenon, JLL (Technology Advisory) | I10: R - Responsible | J10: S - Support | K10: S - Support | L10: S - Support | M10: S - Support | N10: S - Support | O10: S - Support | P10: S - Support | Q10: S - Support | R10: S - Support | S10: S - Support | T10: S - Support
A11: 1 | B11: Xây dựng Chiến lược CNTT & Chuyển đổi số BĐS/Chiến lược PropTech | C11: Định hướng CNTT trở thành nền tảng cốt lõi cho phát triển – quản lý – đầu tư BĐS | D11: Ban hành Chiến lược CNTT & DX 2026–2030 gắn với chiến lược Tập đoàn
A12: 3 | B12: Chiến lược Dữ liệu & AI | C12: Xem dữ liệu là tài sản (Data as Asset) | D12: Khung Data Strategy, AI Strategy, danh mục use-case ưu tiên
A13: 4 | B13: Kiến trúc CNTT & Nền tảng số | C13: Chuẩn hóa kiến trúc ứng dụng – hạ tầng | D13: Enterprise Architecture, Application Map, Integration Blueprint
A14: 5 | B14: Chiến lược An toàn thông tin & Quản trị rủi ro | C14: Bảo vệ tài sản số và tuân thủ | D14: Khung Cybersecurity, DRP, BCP, Zero Trust
A15: 6 | B15: Chiến lược ERP & Hệ thống lõi | C15: Hiện đại hóa hệ thống tài chính – vận hành | D15: Lộ trình ERP (Cloud/Hybrid), thay thế/chuẩn hóa hệ thống
A16: 7 | B16: Chiến lược IT Governance | C16: Minh bạch quản trị CNTT | D16: Minh bạch quản trị CNTT
A17: 8 | B17: Chiến lược Nhân sự CNTT | C17: Xây dựng đội ngũ CNTT chiến lược | D17: IT Skill, kế hoạch đào tạo & tuyển dụng
A18: II | B18: THỰC THI CHIẾN LƯỢC/STRATEGY IMPLEMENTATION
A19: 1 | B19: Triển khai ERP & Core Systems Triển khai Data Platform & BI, [Integration & Automation (API, AI),] | C19: Chuẩn hóa tài chính – kế toán – quản trị | D19: ERP vận hành ổn định, dữ liệu tập trung | F19: HỆ SINH THÁI BITEXCO | G19: SAP/BRAVO/MISA/FPT/CITEX | H19: =ACC_FIN!C13 -> 21.85 | I19: A - Accountable | J19: R - Responsible | K19: S - Support | L19: S - Support | M19: S - Support | N19: S - Support | O19: S - Support | P19: S - Support | Q19: S - Support | R19: S - Support | S19: S - Support | T19: S - Support
B20: HRM, Portal, eContract, eInvoice, DMS/Adm | C20: Chuẩn hoá quản trị nhân sự | D20: Xây dựng Digital Workplace thống nhất, số hóa toàn bộ quản trị nhân sự | F20: BITEXCO PROPERTY | G20: FPT IS/Gimasys/CMC TS/Misa/VNPT iOffice/SAP-SuccessFactors/BRAVO/.. | H20: ='HR.ADM.LEGAL'!E20 -> 2.03 | I20: A - Accountable | J20: S - Support | K20: S - Support | L20: R - Responsible | M20: S - Support | N20: R - Responsible | O20: S - Support | P20: S - Support | Q20: R - Responsible | R20: S - Support | S20: R - Responsible | T20: R - Responsible
B21: Office365/Clound: Sharepoint, AI, Communication, MeetingRoom,.WorkSpace. | F21: HỆ SINH THÁI BITEXCO | G21: VIIETTEL, FPT | H21: =DMD!C3 -> 2.75
A22: 2 | B22: CDP – Data Marketing; CRM (AURA,GD,TMCP,BFT), BitexcoOne/Loyalty, | C22: Ra quyết định dựa trên dữ liệu | D22: Data Warehouse, CDP, BI Dashboard cho BOD | F22: BITEXCO PROPERTY | G22: FPT Digital, Gimasys, FPT Software, CMC TS, Salesforce, Deloitte/FPT, Microsoft, FPT IS, VNPAY, Itel | H22: =MKT.SALES!D26 -> 5 | I22: A - Accountable | J22: R - Responsible | K22: S - Support | L22: S - Support | M22: S - Support | N22: S - Support | O22: S - Support | P22: S - Support | Q22: S - Support | R22: S - Support
A23: 3 | B23: 1>Triển khai AI & Automation/MarTech Platform 2>Performance Marketing (Lead Generation) 3>Content – Website – Landing Page 4>Omni-channel & Automation | C23: Tăng hiệu suất, giảm chi phí vận hành | D23: AI Agents, RPA cho Finance, HR, Leasing | F23: BITEXCO PROPERTY | G23: FPT Software, CMC TS, DXC Technology, ITEL. Novaon Digital PMAX, CleverAds | H23: =MKT.SALES!D18 -> 3 | I23: A - Accountable | J23: S - Support | K23: S - Support | M23: R - Responsible | N23: S - Support | O23: S - Support | P23: R - Responsible | Q23: S - Support | R23: S - Support | S23: S - Support | T23: S - Support
B24: 5>POS, Hospitality sercies | F24: Garden,Fitness, | G24: CMC | H24: =1.9 -> 1.9
A25: 4 | B25: 1>Quản lý tài sản BĐS (CAFM, P.PMS) 2>QL Vận hành – bảo trì: CMS, Mobi, 3>Smart Building & Building Systems (BMS, IoT Sensors) 5>Data – AI cho BĐS, BIM, TENDER Integration & Automation (API, AI) | C25: Số hóa vận hành BĐS | D25: BIM, CMMS, CAFM, BMS tích hợp | F25: BITEXCO PROPERTY | G25: Planon (JLL, Savills), Spacewell (FM, IoT), IBM Maximo (FPT, CMC), Schneider Electric, Siemens, Honeywell, MRI Software (Ls, Tenant), SAP RE-FX Autodesk. FPT Digital, DXC Technology, CMS TS. | H25: ='PMU.QS.EPL'!E35 -> 5.6 | I25: A - Accountable | J25: S - Support | K25: R - Responsible | L25: S - Support | M25: R - Responsible | N25: R - Responsible | O25: S - Support | P25: S - Support | Q25: R - Responsible | R25: S - Support | S25: S - Support | T25: S - Support
A26: 5 | B26: Nền tảng lõi quản lý dự án & thiết kế (PDP) (Core Project & Design Platform (PDP)) | C26: DX for DMD, PDD | D26: PDP, approval workflows, BIM/CDE, data standards | F26: BITEXCO PROPERTY | G26: Planon (JLL, Savills), Spacewell (FM, IoT), IBM Maximo (FPT, CMC), Schneider Electric, Siemens, Honeywell, MRI Software (Ls, Tenant), SAP RE-FX Autodesk. FPT Digital, DXC Technology, CMS TS. | H26: =DMD!C5 -> 5.3
A27: 6 | B27: 1GIS Landbank & Risk Platform Best Use Analysis Tool Feasibility Engine (Living Financial Model) | C27: DX For PDD | D27: 1GIS Landbank & Risk Platform Best Use Analysis Tool Feasibility Engine (Living Financial Model) | H27: 4.7
A28: 5 | B28: Leasing & Tenant system, C.PMS (Quản lý cư dân) | C28: Liên thông dữ liệu toàn hệ sinh thái | D28: ESB/API Gateway hoạt động ổn định | F28: BITEXCO PROPERTY | G28: FPT, CMC, Viettel,DXC Technology | H28: 1.6 | I28: A - Accountable | J28: S - Support | K28: R - Responsible | L28: S - Support | M28: R - Responsible | N28: S - Support | O28: S - Support | P28: S - Support | Q28: R - Responsible | R28: S - Support | S28: S - Support | T28: S - Support
A29: 6 | B29: Chuyển đổi hạ tầng CNTT | C29: Đảm bảo hiệu năng – sẵn sàng cao | D29: Cloud/Hybrid, HA, DR site | F29: BITEXCO PROPERTY | G29: FPT, CMC, Viettel,DXC Technology | H29: 2.5
A30: 7 | B30: Thực thi An toàn thông tin, chuẩn hoá dữ liệu, ứng dụng | C30: Giảm thiểu rủi ro CNTT | D30: IAM, MFA, EDR/XDR, SIEM | F30: BITEXCO PROPERTY | G30: FPT, CMC, Viettel,DXC Technology
A31: 8 | B31: Quản lý dự án CNTT | C31: Đảm bảo tiến độ – chất lượng | D31: PMO CNTT, chuẩn Agile/Waterfall | F31: BITEXCO PROPERTY
A32: 9 | B32: Chuẩn hóa vận hành CNTT | C32: Tăng tính ổn định hệ thống | D32: ITIL processes, SOP CNTT | F32: BITEXCO PROPERTY
A33: 10 | B33: Quản lý nhà cung cấp CNTT, | C33: Tối ưu chi phí & chất lượng | D33: Tối ưu chi phí & chất lượng, SLA (Service Level Agreement) | F33: BITEXCO PROPERTY
A34: 11 | B34: Số hoá dự án, văn phòng số ((SAN, Hyperid, SP) | C34: Số hoá, tập trung và quản trị toàn bộ hồ sơ của doanh nghiệp BĐS theo vòng đời, | D34: Giảm thời gian tìm kiếm hồ sơ | F34: BITEXCO PROPERTY | G34: FPT, CMC, Viettel,DXC Technology | I34: A - Accountable | J34: S - Support | K34: R - Responsible | L34: S - Support | M34: R - Responsible | N34: R - Responsible | O34: S - Support | P34: S - Support | Q34: R - Responsible | R34: S - Support | S34: R - Responsible | T34: R - Responsible
A35: 12 | B35: POS,
A36: III | B36: VẬN HÀNH/ OPERATION
A37: 1 | B37: Vận hành hệ thống CNTT | C37: Đảm bảo hệ thống ổn định 24/7 | D37: Uptime ≥ 99.9%, SLA đạt cam kết | F37: BITEXCO PROPERTY | I37: C - Consult | J37: R - Responsible | K37: R - Responsible | L37: R - Responsible | M37: R - Responsible | N37: R - Responsible | O37: R - Responsible | P37: R - Responsible | Q37: R - Responsible | R37: R - Responsible | S37: R - Responsible | T37: R - Responsible
A38: 2 | B38: Hỗ trợ người dùng & nghiệp vụ | C38: CNTT phục vụ kinh doanh | D38: Service Desk,Uptime ≥ 90% | F38: BITEXCO PROPERTY
A39: 3 | B39: Quản lý tài sản CNTT | C39: Kiểm soát chi phí và vòng đời | D39: IT Asset Management, License Compliance | F39: BITEXCO PROPERTY
A40: IV | B40: OTHERS
...

Sheet JSC_Detail
A1: IT PROJECTS PLANNING
A2: IT Projects | B2: Duration: Dec, 2026
A3: Project | B3: Item | C3: Cost (Million) | D3: B.Parter | E3: Start Date | F3: End Date | G3: Status | H3: Jan | L3: Feb | P3: March | T3: April | X3: May | AB3: June | AF3: July | AJ3: Aug | AN3: Sept | AR3: Oct | AV3: Nov | AZ3: Dec
A4: OPEX & CAPEX | H4: Week 1 | I4: Week 2 | J4: Week 3 | K4: Week 4 | L4: Week 1 | M4: Week 2 | N4: Week 3 | O4: Week 4 | P4: Week 1 | Q4: Week 2 | R4: Week 3 | S4: Week 4 | T4: Week 1 | U4: Week 2 | V4: Week 3 | W4: Week 4 | X4: Week 1 | Y4: Week 2 | Z4: Week 3 | AA4: Week 4 | AB4: Week 1 | AC4: Week 2 | AD4: Week 3 | AE4: Week 4 | AF4: Week 1 | AG4: Week 2 | AH4: Week 3 | AI4: Week 4 | AJ4: Week 1 | AK4: Week 2 | AL4: Week 3 | AM4: Week 4 | AN4: Week 1 | AO4: Week 2 | AP4: Week 3 | AQ4: Week 4 | AR4: Week 1 | AS4: Week 2 | AT4: Week 3 | AU4: Week 4 | AV4: Week 1 | AW4: Week 2 | AX4: Week 3 | AY4: Week 4 | AZ4: Week 1 | BA4: Week 2 | BB4: Week 3 | BC4: Week 4
A5: BITEXCO JSC | B5: 02.System Administration & Infrastructure/Network | C5: =SUM(C6:C26) -> 2325.69
B6: Mua mới máy tính cho CBNV mới (dự kiến theo HR gửi thông tin ) | C6: 420 | E6: 47609 | F6: 47613 | G6: ✅ Completed
B7: Network system, Licenses (duy trì SSL, Domain) | C7: 16 | E7: 47616 | F7: 47620 | G7: ✏️ In progress
B8: Network system, Leadline Viettel | C8: 62 | E8: 47623 | F8: 47627 | G8: 👀 Under review
B9: Office365 - 18 Cloud lưu trữ JSC | C9: 28.2
B10: Apples account. - yearly ($99) | C10: 2.6
B11: Google Acc DEV | C11: 5
B12: Nâng cấp hệ thống bảo mật mail, và chống spam mail | C12: 220
B13: License Antivirus Symantec JSC ( 90PC ) | C13: 40
B14: Chi phí dự phòng sửa chữa nâng cấp JSC | C14: 80
B15: Hệ thống wifi, máy chủ OV tòa tây | C15: 230
B16: Chi phí license windows, SQL, cho máy chủ | C16: 80
B17: Mua dụng cụ sửa chữa thay thế máy tính, mạng… | C17: 30
B18: Mua mới 10 user office 365 Basic | C18: 26.985
B19: Nâng cấp ổ cứng lưu trữ cho hệ thống SAN Storage | C19: 26.985
B20: Nâng cấp dung lượng và bộ nhớ RAM cho máy chủ mail ngày càng phình to | C20: 86.32
... B23: Xây dựng mói phòng máy chủ xuống hầm B2 GD theo chỉ đạo của MD Hà với S=35m2 | C23: 250
B24: Mua mới 02 Lap thiết kế, 01 PC thiết kế chạy AI
B25: Gia hạn Zoommeting 03 acc | C25: 9.6
B26: Xây dựng Private Cloud ( mua platform Redhat dựng trên TB phần cứng của mình) | C26: 600
B27: 03.Application Development & Solution Management | C27: =SUM(C28:C36) -> 33069.5
B28: Xây dựng lại hệ thống ERP (SAP/BRAVO/MISA) | C28: 19725
B29: DX: AKChain (UX,CX,Loyalty, CDP-Dulieu Khach hang)/BItexcoOne | C29: 2311.36 | D29: MKT, IT
B30: DX: AKInsight (Data Lake, BIj) | C30: 3688.64
B31: Datalake for each specialized field | C31: 2000
B32: BI design (DB, UI, UX, ACCOUNT) | C32: 800
B33: Báo cáo quản trị/ERP/BRAVO | C33: 2000
B34: Hệ thống quản lý nhân sự (HRM) | C34: 1644.5
B35: Portal Upgd/EA/ABSENT/VPP/…/eOffice (VP SỐ) | D35: IT
B36: Server for DC (Dự tính server triển khai TC_KT: 3 Server (1:App, 2: Core)) | C36: 900
B37: TENDER/PURCHASING management system | D37: IT, QS, EPL
B38: KPI; Portal; BitexcoRun; PDS; AMS; POS/CRM; BitexcoSport;.. | D38: IT
B39: HỆ THỐNG QUẢN LÝ TOÀ NHÀ, TENANT (For HighRise & Block13) | C39: 1200
B40: 04.Data Center, PMO & Digital Projects
B41: Wifi Marketing, Websites | D41: TMCP, BFT, AURA, NANO, ENERGY, GARDEN, MQ,
B42: CCTV TTTM, Mkt-Flatform | D42: Garden, TMCP,
...

Sheet ACC_FIN
A1: BUDGET CNTT PHỤC VỤ DX TÀI CHÍNH – KẾ TOÁN
A2: Nhóm hệ thống / System Category (VN/EN) | B2: Hệ thống – Giải pháp & Vai trò (VN / EN) | C2: Budget Year 1 (tỷ) | D2: Vendor
A3: ERP lõi / Core ERP | B3: ERP quản lý Tài chính – Kế toán end-to-end / End-to-end Finance & Accounting ERP | C3: 16.53 | D3: BRAVO
A4: Hợp nhất BCTC / Financial Consolidation | B4: Hợp nhất báo cáo tài chính Tập đoàn (VAS/IFRS) / Group financial consolidation | C4: 3.97 | D4: BRAVO/FPT
A5: Ngân hàng điện tử / e-Banking Integration | B5: Kết nối ngân hàng, UNC, đối soát & hạch toán tự động / Bank integration & reconciliation | C5: 0.08 | D5: Bank + BRAVO
A6: Hóa đơn điện tử / e-Invoice | B6: Phát hành & hạch toán hóa đơn điện tử tích hợp ERP / e-Invoice integrated with ERP | C6: 0.03 | D6: VNPT / Viettel
A7: Hợp đồng điện tử & Ký số / e-Contract & Digital Signature | B7: Ký hợp đồng, hồ sơ thanh toán điện tử / Digital contract signing | C7: 0.05 | D7: FPT / Bkav/Viettel
A8: Kho hồ sơ số / Data Room – DMS | B8: Lưu trữ & chia sẻ hồ sơ dự án, hợp đồng theo phân quyền / Secure data room & document management | C8: 0.3 | D8: Microsoft
A9: Workflow & EA thay thế / Workflow & EA Replacement | B9: Phê duyệt chủ trương, PO, Payment Request trên ERP / Approval workflow replacing legacy EA | C9: 0.4 | D9: BRAVO
A10: Báo cáo quản trị / BI & Dashboards | B10: Dashboard CFO/BOD, báo cáo real-time / Management dashboards & BI | C10: 0.25 | D10: Microsoft
A11: Văn phòng số / Digital Workplace | B11: Email, Teams, chia sẻ & cộng tác nội bộ / Digital workplace & internal collaboration | C11: 0.04 | D11: Microsoft | E11: TC,KT: 15P*215K*12
A12: AI hỗ trợ nghiệp vụ / AI Support (Basic) | B12: AI/Copilot hỗ trợ báo cáo, cập nhật pháp lý, công việc chuyên môn / AI & Copilot basic support | C12: 0.2 | D12: Microsoft
A13: Tổng cộng | C13: =SUM(C3:C12) -> 21.85

Sheet MKT.SALES
A1: LEVEL 1 – DATA FOUNDATION (BẮT BUỘC LÀM TRƯỚC)
A3: Group (Nhóm) | B3: System (Hệ thống) | C3: Role (Vai trò) | D3: Budget MIN | E3: Vendor gợi ý
A4: Data | B4: CRM | C4: Lead & customer management / Quản lý lead & KH | D4: 2 | E4: Zoho, Odoo
A5: Project | B5: AIM | C5: Project & product info / Hồ sơ dự án, sản phẩm | D5: 1.5 | E5: In-house (Infra, Tools)
A6: Analytics | B6: AI Market Research | C6: Market trend & pricing / Phân tích thị trường | D6: 0.8 | E6: AI Agent + tool
A7: Platform | B7: Integration | C7: CRM–Web–Sales sync / Đồng bộ dữ liệu | D7: 0.5 | E7: In-house
A8: Digital Workplace | B8: Email, SharePoint, Teams, AI, office & BIM tools, training
A9: TOTAL LEVEL 1 (năm đầu) | D9: =SUM(D4:D7) -> 4.8
A11: LEVEL 2 – REVENUE ENGINE (LÀM GỌN – TẠO DOANH THU)
A13: Group | B13: System | C13: Role | D13: Budget MIN | E13: Vendor
A14: Experience | B14: Web Sales / VR nhẹ | C14: Project presentation / Trình diễn dự án | D14: 1.5 | E14: ITEL
A15: Sales Ops | B15: SMS | C15: Sales pipeline & booking / Quản lý bán hàng | D15: 1 | E15: In-house (Infra, Tools)
A16: Marketing | B16: Marketing Automation | C16: Email/SMS basic / Chăm sóc KH cơ bản | D16: 0.8 | E16: SaaS
A17: Platform | B17: Integration (gộp) | C17: Realtime data sync / Đồng bộ realtime | D17: 0.5 | E17: In-house (Infra, Tools)
A18: TOTAL LEVEL 2 (năm hai) | D18: =SUM(D14:D17) -> 3
A20: LEVEL 3 – STRATEGIC INTELLIGENCE (CHỈ LÀM MỨC CƠ BẢN)
A21: Group | B21: System | C21: Role | D21: Budget MIN | E21: Vendor
A22: Data | B22: Data Mart (CDP Core) | C22: Central sales data / Dữ liệu bán hàng | D22: 2 | E22: Azure SQL
A23: Management | B23: Strategic Dashboard | C23: BOD dashboard / Dashboard lãnh đạo | D23: 1 | E23: Power BI
A24: Analytics | B24: ALM (basic scenario) | C24: Simple IRR scenario / Kịch bản cơ bản | D24: 1.5 | E24: In-house (Infra, Tools)
A25: Governance | B25: Data Security | C25: Access control / Phân quyền dữ liệu | D25: 0.5 | E25: M365
A26: TOTAL LEVEL 3 (năm ba) | D26: =SUM(D22:D25) -> 5
A29: OVERALL MINIMUM BUDGET SUMMARY (NGÂN SÁCH TỐI THIỂU)
A30: Level | D30: Budget (tỷ VNĐ)
A31: Level 1 – Data Foundation | D31: =D9 -> 4.8
A32: Level 2 – Revenue Engine | D32: =D18 -> 3
A33: Level 3 – Strategic Intelligence | D33: =D26 -> 5
A34: TOTAL DX SALES & MARKETING (MIN) | D34: =SUM(D31:D33) -> 12.8

Sheet HR.ADM.LEGAL
A1: BẢNG BUDGET TỔNG HỢP – HR & ADMIN (Song ngữ VN/EN – gộp 1 cột)
A3: Nhóm (Group) | B3: Hệ thống / Ứng dụng (System) | C3: Vai trò / Chức năng chính (Role) | D3: Hình thức (Type) | E3: Budget (Tỷ VND/năm) | F3: Vendor tham khảo
A4: HR | B4: HRM Core (Hồ sơ nhân sự, HĐLĐ, BHXH) | C4: Quản lý hồ sơ nhân sự, hợp đồng, quá trình công tác | D4: SaaS | E4: 0.25 | F4: Base HRM / Odoo HR | G4: 6,6tỷ/30đơn vị | H4: =6.6/30 -> 0.22
A5: HR | B5: Payroll (Tính lương) | C5: Tính lương, thuế TNCN, BHXH | D5: Module | E5: 0.15 | F5: Tích hợp HRM
A6: HR | B6: Time Attendance (Chấm công) | C6: Chấm công, ca kíp, OT | D6: SaaS | E6: 0.1 | F6: WiseEye / FaceID
A7: HR | B7: Recruitment (Tuyển dụng) | C7: Quản lý tuyển dụng, CV, phỏng vấn | D7: SaaS | E7: 0.08 | F7: Base Hiring
A8: HR | B8: Performance & KPI | C8: Đánh giá hiệu suất, KPI | D8: SaaS | E8: 0.1 | F8: Base Performance
A9: HR | B9: eLearning / Training | C9: Đào tạo nội bộ, LMS | D9: SaaS | E9: 0.07 | F9: Moodle Cloud
A10: HR | B10: eSign / eContract | C10: Ký HĐLĐ điện tử | D10: SaaS | E10: 0.05 | F10: FPT.eSign
A11: ADMIN | B11: DMS – Văn thư lưu trữ | C11: Quản lý công văn đi/đến, hồ sơ pháp lý, hồ sơ dự án | D11: SaaS | E11: 0.35 | F11: SharePoint / DMS VN
A12: Admin | B12: Asset Management (Tài sản) | C12: Quản lý TS, xe, thiết bị VP | D12: SaaS | E12: 0.2 | F12: Odoo Asset
A13: Admin | B13: Facility / Office Management | C13: Quản lý phòng họp, thiết bị, booking | D13: SaaS | E13: 0.1 | F13: Microsoft 365
A14: Admin | B14: Reminder & Scheduler | C14: Nhắc việc, nhắc lịch, sự kiện nội bộ | D14: SaaS | E14: 0.05 | F14: Power Automate
A15: Admin | B15: Event Management | C15: Đăng ký sự kiện, gửi thư mời, khảo sát | D15: SaaS | E15: 0.08 | F15: MS Forms / Event App
A16: DÙNG CHUNG | B16: Digital Workplace | C16: Email, Teams, SharePoint (15–30 users) | D16: SaaS | E16: 0.1 | F16: Microsoft 365 Std
... A19: Triển khai | B19: PM, Training, Change | C19: Quản lý dự án, đào tạo người dùng | D19: One-off | E19: 0.15 | F19: IT nội bộ / Vendor
B20: Tổng cộng | E20: =SUM(E4:E19) -> 2.03

Sheet DMD
A1: Ngân sách CNTT năm 2026 cho DMD/BITEXCO
A2: Chương trình chiến lược (Strategic Program) | B2: Nội dung chính (Key Scope) | C2: Ngân sách (Budget) – Bilion VND | D2: Giá trị mang lại cho Cty (Group Value) | E2: Type ứng dụng (Application Type) | F2: BD Unit | G2: Suppliers
A3: 1. Nền tảng làm việc số & con người (Digital Workplace & People) | B3: Email, SharePoint, Teams, AI, office & BIM tools, training | C3: 2.75 | D3: Làm việc thống nhất, chuyên nghiệp, giảm phụ thuộc cá nhân (Unified, professional working environment) | E3: Software / License / Service | F3: DMD/IT | G3: FPT/CMC/DXD
A4: 2. Thiết bị & năng lực thực thi (End-user Readiness) | B4: Laptops, screens, working devices (12p*50) | C4: 0.6 | D4: Đảm bảo năng lực thực thi dự án & thiết kế (Ensures execution capability) | E4: Hardware | F4: IT
A5: 3. Nền tảng lõi quản lý dự án & thiết kế (PDP) (Core Project & Design Platform (PDP)) | B5: PDP, approval workflows, BIM/CDE, data standards | C5: 5.3 | D5: Quản lý & bảo toàn tài sản dự án Dự án = tài sản dữ liệu, giảm rủi ro pháp lý (Projects become long-term data assets) | E5: Software / Platform License / Implementation | F5: DMD/IT
A6: 4. Chuẩn hóa quy trình & dữ liệu tập đoàn (Enterprise Process & Data Foundation) | B6: Standard workflows, master data | D6: Minh bạch, nhất quán, nền tảng quản trị (Consistency & governance foundation) | E6: Software / Consulting
A7: 5. Báo cáo điều hành & ra quyết định (Executive Reporting & BI) | B7: BI dashboards, management reports | C7: 1.5 | D7: Ra quyết định dựa trên dữ liệu (Data-driven decision making) | E7: Software / License | F7: Accounting, Finance
A8: 6. Tự động hóa & hiệu suất (Automation & Productivity) | B8: Automation platform & use cases | D8: Giảm chi phí vận hành, tăng hiệu suất (Lower OPEX, higher efficiency) | E8: Platform / Software
A9: TỔNG CỘNG / TOTAL | C9: =SUM(C3:C8) -> 10.15 | D9: Nền tảng chuyển Bitexco sang PropTech & mô hình đầu tư (Foundation for PropTech & investment-driven model)

Sheet PDD
A1: Ngân sách CNTT năm 2026 cho PDD/BITEXCO
A2: Khối chức năng (Functional Block) | B2: Giá trị mang lại cho Cty (Group Value) | C2: Ngân sách (Budget) Đơn vị (tỷ đồng) - Billiion VND | D2: Type ứng dụng (Application Type) | E2: Đơn vị cung cấp (Vendors)
A3: 1GIS Landbank & Risk Platform | B3: Số hóa landbank trọng điểm; lớp quy hoạch, pháp lý, hạ tầng (Key landbank; planning, legal & infrastructure layers) | C3: 1.8 | D3: SaaS GIS / GIS License | E3: Esri (ArcGIS) Map4D VNPT IT
A4: Best Use Analysis Tool | B4: Logic rule-based theo quy hoạch + thị trường; (Rule-based, no advanced optimization) | C4: 0.6 | D4: Custom tool / BI-based | E4: FPT IS/CMC LS
A5: Feasibility Engine (Living Financial Model) | B5: Mô hình tài chính chuẩn; 5–7 biến số nhạy cảm (Standard model; key sensitivity scenarios) | C5: 1 | D5: Custom software / Financial model | E5: Deloitte Vietnam PwC Vietnam KPMG Vietnam
A6: Data Platform & Integration (light) | B6: Power BI + Dataflow/SQL; (No full-scale data lake) | C6: 1 | D6: SaaS BI / Light data platform | E6: Microsoft (Power BI, SQL)/FPT IS
A7: Dashboard IC/BI/BO & Reporting | B7: Dashboard gọn: bản đồ – phương án – hiệu quả (Map – options – financial outcomes) | C7: 0.3 | D7: SaaS BI / License | E7: Microsoft (Power BI)/Tableau
A8: PM, Training, Change Management | B8: PM tinh gọn; đào tạo theo vai trò (Lean PM & role-based training) | D8: Service | E8: Đối tác triển khai + nội bộ (Implementation partner + internal team)
A9: Email, SharePoint, Teams, AI, office & BIM tools, training | B9: Nền tảng làm việc chung
A10: TỔNG CỘNG / TOTAL | C10: =SUM(C3:C9) -> 4.7

Sheet PMU.QS.EPL
A1: BẢNG BÁO GIÁ DỊCH VỤ TRIỂN KHAI TENDER (ITEL)
A3: Kính gửi: | C3: Bitexco JSC
A4: Chúng tôi xin gửi tới Quý khách hàng bảng chào giá dịch vụ triển khai Hệ thống Đấu thầu qua mạng như sau: | I4: VNĐ
A5: STT | B5: Mã hiệu | C5: Mô tả hàng hóa/dịch vụ | D5: Mô tả chi tiết | E5: Số lượng/Man-day | F5: Đơn giá | G5: Thành tiền (chưa VAT) | H5: Thuế VAT (10%) | I5: Thành tiền (Bao gồm VAT)
A6: 1 | B6: E-CORE | C6: Hệ thống Core eBidding | D6: - Bản quyền sử dụng hệ thống core - Bao gồm các tính năng cơ bản theo yêu cầu - Hỗ trợ đầy đủ quy trình đấu thầu qua mạng | E6: 1 | F6: 500000000 | G6: 500000000 | H6: 50000000 | I6: 550000000
A7: 2 | B7: E-CUSTOM | C7: Gói tùy chỉnh nghiệp vụ | D7: - Phân tích yêu cầu đặc thù của Bitexco - Tùy chỉnh giao diện và workflow - Tích hợp với hệ thống hiện có | E7: 12.5 | F7: 8000000 | G7: 100000000 | H7: 10000000 | I7: 110000000
A8: 3 | B8: E-SURVEY | C8: Khảo sát & Thiết kế chi tiết | D8: - Khảo sát hiện trạng hệ thống - Phân tích yêu cầu nghiệp vụ - Thiết kế kiến trúc và database | E8: 8 | F8: 5000000 | G8: 40000000 | H8: 4000000 | I8: 44000000
A9: 4 | B9: E-DEV | C9: Phát triển tính năng bổ sung | D9: - Sơ tuyển nhà thầu (Pre-qualification) - Q&A và phát hành phụ lục HSMT - Quản lý deadline động cho từng nhà thầu - Tracking mở HSMT và thông báo tự động | E9: 25 | F9: 7200000 | G9: 180000000 | H9: 18000000 | I9: 198000000
A10: 5 | B10: E-TEST | C10: Kiểm thử UAT | D10: - Kiểm thử tích hợp hệ thống - UAT với người dùng cuối - Đánh giá bảo mật và hiệu năng | E10: 10 | F10: 5000000 | G10: 50000000 | H10: 5000000 | I10: 55000000
A11: 6 | B11: E-TRAIN | C11: Đào tạo người dùng | D11: - Đào tạo admin quản trị hệ thống - Đào tạo cán bộ nghiệp vụ - Đào tạo người dùng cuối (nhà thầu) | E11: 6 | F11: 5000000 | G11: 30000000 | H11: 3000000 | I11: 33000000
A12: 7 | B12: E-DEPLOY | C12: Triển khai hệ thống | D12: - Cài đặt và cấu hình môi trường production - Migration dữ liệu - Go-live và hỗ trợ onsite | E12: 8 | F12: 5000000 | G12: 40000000 | H12: 4000000 | I12: 44000000
A13: 8 | B13: E-DOC | C13: Tài liệu hệ thống | D13: - Tài liệu kỹ thuật hệ thống - Hướng dẫn sử dụng - Quy trình vận hành | E13: 5 | F13: 4000000 | G13: 20000000 | H13: 2000000 | I13: 22000000
A14: 9 | B14: E-SUPPORT | C14: Hỗ trợ bảo hành 12 tháng | D14: - Hỗ trợ vận hành 24/7 - Sửa lỗi và cập nhật - Tư vấn nghiệp vụ | E14: 12 | F14: 10909090 | G14: 130909080 | H14: 13090908 | I14: 143999988
A15: Tổng cộng (chưa bao gồm VAT) | G15: 1090909080 | H15: 109090908 | I15: 1199999988
A18: BẢNG BUDGET PROPTECH – PMU (LOW SCENARIO)
A20: Đơn vị: TỶ VND / NĂM
A22: Nhóm | B22: Hệ thống | C22: Vai trò chính cho PMU | D22: Mô hình | E22: Budget (tỷ) | F22: Ghi chú PMU
A23: 1. Quản lý tài sản BĐS | B23: CAFM / Property PMS | C23: Quản lý tài sản, diện tích, vòng đời | D23: SaaS | E23: 0.8 | F23: Cốt lõi cho mô hình Asset Management
B24: Portfolio PMS (PPMS) | C24: Theo dõi hiệu suất tài sản | D24: SaaS | E24: 0.5 | F24: Dashboard cho PMU & BOD
A25: 2. Vận hành – Bảo trì | B25: CMS (Maintenance) | C25: Quản lý bảo trì, ticket, SLA | D25: SaaS | E25: 0.6 | F25: Thay Excel + Zalo
B26: Mobile Ops App | C26: App cho đội kỹ thuật | D26: License | E26: 0.2 | F26: Giảm thời gian phản hồi
A27: 3. Smart Building | B27: BMS Integration Layer | C27: Kết nối BMS hiện hữu | D27: Integration | E27: 0.6 | F27: Không thay BMS hiện hữu
B28: IoT Sensors (pilot) | C28: Điện, nước, nhiệt độ | D28: HW + SW | E28: 0.5 | F28: Thí điểm khu trọng điểm
A29: 4. Data – AI – BIM – Tender | B29: Data Platform (Light) | C29: Thu thập & chuẩn hóa dữ liệu | D29: Platform | E29: 0.7 | F29: Phục vụ báo cáo & AI
B30: BI Dashboard (PMU/BOD) | C30: Báo cáo vận hành | D30: License | E30: 0.2 | F30: Power BI / tương đương
B31: BIM Ops / Digital Twin (Light) | C31: BIM cho vận hành | D31: SaaS | E31: 0.6 | F31: Không làm BIM thiết kế mới
B32: e-Tender / QL nhà thầu | C32: So sánh giá, lịch sử NCC | D32: SaaS | E32: 0.3 | F32: Minh bạch chi phí
A33: 5. Integration & Automation | B33: API Integration | C33: Kết nối ERP – PMS – CMS – BMS | D33: Platform | E33: 0.4 | F33: Tránh silo hệ thống
B34: AI Automation (basic) | C34: Phân loại ticket, cảnh báo | D34: Add-on | E34: 0.2 | F34: Chưa dùng AI phức tạp
A35: Tổng cộng | E35: =SUM(E23:E34) -> 5.6

Sheet PMG.BHMC.AURA
B1: BUDGET - IT BHMC
B3: THÔNG TIN PHẦN MỀM & THIẾT BỊ | C3: BUDGET AURA CLUB + PMG
C4: Phòng ban liên quan | D4: Loại | E4: Số lượng | F4: Đơn vị | G4: Đơn giá | H4: Chi phí dự kiến (vnd) | I4: Thời hạn kích hoạt chi tiền | J4: Thời hạn hoàn thành | K4: Ghi Chú
B5: PHẦN MỀM QUẢN LÝ CÔNG VIỆC VÀ VẬN HÀNH HỆ THỐNG KINH DOANH | H5: =SUM(H6:H12) -> 942000000
B6: Bảo trì phần mềm Newway ( tương đương 10% giá trị hợp đồng) | C6: IT/EPL/SALE & MARKETING | D6: Software | E6: 1 | F6: AURA | G6: 35000000 | H6: =G6*E6 -> 35000000 | I6: 45962 | J6: 46327 | K6: Bảo trì & bổ sung tính năng tích hợp hệ thống ( Tích hợp kiểm soát vé bể bơi , hội viên đi bơi của SF, quản lý nhân sự …)
B7: Tích hợp hệ thống Newway Loyalty quản lý thông tin khách hàng | C7: IT/SASE & MARKETING | D7: Software | E7: 1 | F7: AURA | G7: 60000000 | H7: =G7*E7 -> 60000000 | I7: 46082 | J7: 46143 | K7: Hệ thống tính điểm, trừ tiền giảm giá, chương trình khyến mã, quản lý thành viên
B8: Tích hợp quản lý ra vào bể bơi & khu vực tầng 5 với hội viên Starfitness, | C8: IT/Fitness Team | D8: Software | E8: 1 | F8: AURA | G8: 40000000 | H8: =G8*E8 -> 40000000 | I8: 45717 | J8: 45778 | K8: Tích hợp Module quản lý bể bơi trên Newway
B9: App vận hành cho ban quản lý | C9: IT/PMG | D9: Software | E9: 1 | F9: PMG | G9: 72000000 | H9: =G9*E9 -> 72000000 | K9: Theo kế hoạch của PMG
B10: Phần mềm quản lý nhân sự | C10: IT/HR Team | D10: Software | E10: 1 | F10: PMG/AURA | G10: 300000000 | H10: =G10*E10 -> 300000000 | K10: Theo kế hoạch của BHMC dự kiến có 150 user tự chia tỷ lệ PMG và AURA
B11: ZALO mini app | C11: IT/Sale & Marketing | D11: Software | E11: 1 | F11: AURA | G11: 85000000 | H11: =G11*E11 -> 85000000 | K11: Theo kế hoạch S&M trình EA
B12: Phần mềm CRM | C12: IT/SALE & MARKETING | D12: Software | E12: 1 | F12: AURA | G12: 350000000 | H12: =G12*E12 -> 350000000 | K12: Theo kế hoạch của AURA
B13: THIẾT BỊ MÁY TÍNH - MÁY VĂN PHÒNG | H13: =SUM(H14:H15) -> 76000000
B14: Máy tính xách tay | C14: IT/EPL/Admin | D14: Hardware | E14: 2 | F14: HCNS-TCKT | G14: 20000000 | H14: =G14*E14 -> 40000000 | J14: 46023 | K14: Định biên mới. Tự chia tỷ lệ Aura và PMG
B15: Máy tính để bàn | C15: IT/EPL/Admin | D15: Hardware | E15: 2 | F15: AURA | G15: 18000000 | H15: =G15*E15 -> 36000000 | J15: 46023 | K15: Nâng cấp hoặc thay mới
B16: Máy ảnh + túi chống ẩm | C16: IT/Admin/S&M | D16: Hardware | E16: 1 | F16: AURA | G16: 48000000 | H16: =G16*E16 -> 48000000 | J16: 46111 | K16: Team MKT chủ động hơn trong việc chụp ảnh các hoạt động dịch vụ cần update hình ảnh daily (tiệc, đồ ăn/uống theo ngày, khách tham gia spa/fitness…) Tiết kiệm hơn các chi phí cho phần thuê outsource bên ngoài
B17: MÁY CHỦ , THIẾT BỊ TƯỜNG LỬA , THIẾT BỊ LƯU TRỮ BACKUP DỮ LIỆU ( chia Pmg/Aura) | H17: =SUM(H18:H21) -> 201000000
B18: Switch Quang 10GB 24Port + Module Quang / đồng 10GB | C18: IT/EPL | D18: System | E18: 1 | F18: PMG | G18: 60000000 | H18: =G18*E18 -> 60000000 | J18: 46143 | K18: Nâng cấp hạ tầng Switch quang cho hệ thống CCTV đồng thời dự phòng cho các switch quang bị lỗi có thể ảnh hưởng đến công tác vận hành
B19: Switch Cisco 9200L-24T-4X riêng cho các Server | C19: IT/EPL/Admin | D19: System | E19: 1 | F19: AURA | G19: 45000000 | H19: =G19*E19 -> 45000000 | J19: 46023 | K19: trang bị nhằm chia tải cho switch core đang bị quá tải do cắm nhiều thiết bị và link hệ thống switch
B20: Thiết bị Storage backup NAS lưu trữ dữ liệu | C20: IT/EPL/Admin | D20: System | E20: 1 | F20: AURA+PMG | G20: 80000000 | H20: =G20*E20 -> 80000000 | I20: 45658 | J20: 45717 | K20: Lưu trữ backup dữ liệu hệ thống máy chủ của Trung tâm dữ liệu đặt tại Aura. Chia tỷ lệ 50/50 cho AURA và PMG
B21: Ổ cứng cho Server Dell R440 | C21: IT/EPL/Admin | D21: System | E21: 2 | F21: AURA+PMG | G21: 8000000 | H21: =G21*E21 -> 16000000 | I21: 46082 | J21: 46111 | K21: Nâng cấp Server để chạy dự phòng cho các máy chủ khác chia tỷ lệ 50/50 cho AURA và PMG
B22: License | H22: =SUM(H23:H27) -> 63000000
B23: SSL/Domain | C23: IT/Purchase | D23: subscription | E23: 1 | F23: AURA | G23: 10000000 | H23: =G23*E23 -> 10000000 | J23: 46113 | K23: auraclub.vn,auraclub.com.vn,bhmc.vn,bhmc.com.vn
B24: License Office 365 | C24: IT/Purchase | D24: subscription | E24: 1 | F24: PMG | G24: 2500000 | H24: =G24*E24 -> 2500000 | I24: 46082 | J24: 46113 | K24: Mua theo năm, sử dụng cho các máy kế toán hoặc HOD
B25: Symantec Endpoint Protection, Subscription License with Support, 1-99 Devices, 1Y | C25: IT/Purchase | D25: subscription | E25: 15 | F25: AURA+PMG | G25: 700000 | H25: =G25*E25 -> 10500000 | I25: 46204 | J25: 46235 | K25: Phần mềm chống virus máy chủ & máy trạm Renew hàng năm chia tỷ lệ 50% cho AURA và 50% cho PMG
B26: License Firewall Fortinet 100F | C26: IT/Purchase | D26: subscription | E26: 1 | F26: AURA+PMG | G26: 40000000 | H26: 40000000 | I26: 46204 | J26: 46235 | K26: Chia tỷ lệ 50/50 cho AURA và PMG
B28: CHI PHÍ PHÁT SINH SỬA CHỮA MÁY TÍNH - BỔ SUNG WIFI - KÉO DÂY MẠNG | H28: =SUM(H29:H32) -> 36500000
B29: bổ sung wifi cho khu vực Celia aura | C29: IT / Kỹ thuật | E29: 2 | F29: AURA | G29: 6000000 | H29: =G29*E29 -> 12000000 | J29: 46054 | K29: đảm bảo sóng phủ đầy phòng tiệc rộng
B30: Nâng cấp ổ cứng máy tính thiết kế và Marketing | C30: IT/Admin/EPL | E30: 2 | F30: AURA | G30: 3000000 | H30: =G30*E30 -> 6000000 | J30: 46054
B31: Thùng dây mạng cat6 + hạt mạng | C31: IT/Admin/EPL | E31: 1 | F31: AURA | G31: 3500000 | H31: =G31*E31 -> 3500000 | J31: 46054 | K31: Phục vụ múc đích sửa chữa, di chuyển , thay đổi
B32: máy lỗi nguồn,ổ cứng, bàn phím, chuột, ram, main , màn hình , sạc …...., dây cable nguồn , dây cable tín hiệu HDMI,VGA, bộ chuyển đổi tín hiệu từ HDMI to VGA ….., vật tư phụ nâng cấp ,sửa chữa thiết bị , công cụ sửa chữa mạng tool dò, dây mạng, hạt mạng, | C32: IT/Admin/EPL | D32: dịch vụ | E32: 1 | F32: AURA+PMG | G32: 15000000 | H32: 15000000 | I32: 45778 | J32: 46386 | K32: Chi phí sửa chữa đột xuất dự trù trong 1 năm liên quan đến việc các thiết bị hỏng đột xuất. ( chia tỷ lệ 50% cho AURA và 50% cho PMG
B33: Total - Tổng giá trị | H33: =H28+H22+#REF!+H17+H13+H5 -> #REF!
B37: Leasing & Tenant system, C.PMS (Quản lý cư dân) | J37: 1,6TỶ
B38: PMS

Sheet BFT.2026
A1: Đơn vị: Bitexco Work Place
A2: Phòng: Phòng CNTT
A4: Ngân sách CNTT năm 2026 cho Bitexco WorkPlace
A6: No. | B6: Hệ thống | C6: Máy móc/Thiết bị đề nghị | D6: Nhóm | E6: Ngân sách năm | F6: Số lượng | G6: ĐVT | H6: Đơn giá (VNĐ) | I6: Thành tiền (VNĐ) | J6: VAT (10%) | K6: Thành tiền - Include VAT (VNĐ) | L6: Thời gian thực hiện | M6: Ghi chú
A7: 1 | B7: Device License | C7: FortiGate 201E Firewall License | D7: General | E7: 2026 | F7: 1 | G7: license | H7: 32000000 | I7: =H7*F7 -> 32000000 | J7: =I7*0 -> 0 | K7: =SUM(I7:J7) -> 32000000 | L7: 01/2026 | M7: Chi phí gia hạn License cho 1 năm, hết hạn ngày 01/2026
A8: 2 | B8: SSD Server | C8: HPE 960GB SATA 6G Read Intensive SFF (2.5in) | D8: Office | E8: 2026 | F8: 2 | G8: Cái | H8: 13560000 | I8: =H8*F8 -> 27120000 | J8: =I8*0.1 -> 2712000 | K8: =SUM(I8:J8) -> 29832000 | L8: 02/2026
B9: SAN | C9: Hệ thống lưu trữ tập trung SAN HPE | D9: Office | E9: 2026 | F9: 1 | G9: HT | H9: 900000000 | I9: =H9*F9 -> 900000000 | J9: =I9*0.1 -> 90000000 | K9: =SUM(I9:J9) -> 990000000
B10: Core Switch | C10: HPE Aruba Networking CX 6300M 24-port 1GbE and 4-port SFP56 Core Switch | D10: Office | E10: 2026 | F10: 2 | G10: Cái | H10: 147000000 | I10: =H10*F10 -> 294000000 | J10: =I10*0.1 -> 29400000 | K10: =SUM(I10:J10) -> 323400000
A11: 3 | B11: Softwares License | C11: Symantec Endpoint Protection License | D11: Office | E11: 2026 | F11: 53 | G11: license | H11: 450000 | I11: =H11*F11 -> 23850000 | J11: =I11*0 -> 0 | K11: =SUM(I11:J11) -> 23850000 | L11: 06/2026 | M11: Chi phí gia hạn License cho 1 năm, hết hạn vào 06//2026
A12: 4 | C12: Phần mềm Zoom Pro License | D12: Office | E12: 2026 | F12: 1 | G12: license | H12: 3200000 | I12: =H12*F12 -> 3200000 | J12: =I12*0 -> 0 | K12: =SUM(I12:J12) -> 3200000 | L12: 11/2026 | M12: Chi phí gia hạn License cho 1 năm, hết hạn vào 11//2026
A13: 5 | C13: Windows 11 Pro License | D13: Office | E13: 2026 | F13: 45 | G13: License | H13: 3200000 | I13: =H13*F13 -> 144000000 | J13: =H13*0.1 -> 320000 | K13: =SUM(I13:J13) -> 144320000 | L13: 02/2026 | M13: - Nâng cấp cho máy tính CBNV
A14: 6 | C14: Microsoft 365 personal (QQ2-00003) License | D14: Office | E14: 2026 | F14: 45 | G14: License | H14: 1680000 | I14: =H14*F14 -> 75600000 | J14: =H14*0.1 -> 168000 | K14: =SUM(I14:J14) -> 75768000 | L14: 02/2026 | M14: - Nâng cấp cho máy tính CBNV
A15: 7 | C15: ChatGPT Business cho cấp quản lý (gói 12 tháng). | D15: Office | E15: 2026 | F15: 15 | G15: License | H15: 10300000 | I15: =H15*F15 -> 154500000 | J15: 0 | K15: =SUM(I15:J15) -> 154500000 | L15: 01/2026 | M15: - Mua cho các vị trí cấp quản lý của các Phòng ban sử dụng khi chưa có Hệ thống AI tổng thể được đầu tư.
A16: 8 | C16: Phần mềm AutoCAD - including specialized toolsets AD Commercial New Single-user ELD Annual Subscription- Thời gian sử dụng 1 năm- Hỗ trợ kỹ thuật, cập nhật 1 năm đầu miễn phí | D16: Office | E16: 2026 | F16: 10 | G16: License | H16: 37500000 | I16: =H16*F16 -> 375000000 | J16: 0 | K16: =SUM(I16:J16) -> 375000000 | L16: 04/2026 | M16: - Dự kiến mua Mua cho phòng DMD, Design và Kỹ thuật - Các hảng này đã có 1 hãng gửi công văn y/c bản quyền đến Tập đoàn. Trong năm 2026 sẽ còn rà soát mạnh hơn nên cần có chi phí dự trù đầu tư.
A17: 9 | C17: Phần mềm 3ds Max 2026 Commercial New Single-user ELD Annual Subscription- Thời gian sử dụng 1 năm- Hỗ trợ kỹ thuật, cập nhật 1 năm đầu miễn phí | D17: Office | E17: 2026 | F17: 4 | G17: License | H17: 35900000 | I17: =H17*F17 -> 143600000 | J17: 0 | K17: =SUM(I17:J17) -> 143600000 | L17: 04/2026
A18: 10 | C18: Phần mềm V-Ray Solo (named, annual) | D18: Office | E18: 2026 | F18: 3 | G18: License | H18: 13600000 | I18: =H18*F18 -> 40800000 | J18: 0 | K18: =SUM(I18:J18) -> 40800000 | L18: 01/2026
A19: 11 | C19: Phần mềm Photoshop for teams ALL Multiple Platforms Multi Asian Languages Subscription New 12 Months | D19: Office | E19: 2026 | F19: 4 | G19: License | H19: 11500000 | I19: =H19*F19 -> 46000000 | J19: 0 | K19: =SUM(I19:J19) -> 46000000 | L19: 04/2026
A20: 12 | C20: Phần mềm Illustrator for teams ALL Multiple Platforms Multi Asian Languages Subscription New 12 Months | D20: Office | E20: 2026 | F20: 4 | G20: License | H20: 11500000 | I20: =H20*F20 -> 46000000 | J20: 0 | K20: =SUM(I20:J20) -> 46000000 | L20: 04/2026
A21: 13 | B21: SAP system | C21: Chi phí bảo trì và quản lý cho Hệ thống SAP với Tập đoàn (HO) | D21: Office | E21: 2026 | F21: 1 | G21: Gói | H21: 113400000 | I21: =H21*F21 -> 113400000 | J21: =H21*0.1 -> 11340000 | K21: =SUM(I21:J21) -> 124740000 | L21: 12/2026 | M21: - Hợp đồng dịch vụ giữa BWP và HO hết hạn vào 31/12/2025 - Phí bảo trì: 6,200,000 * 12 user = 74,400,000 VNĐ/năm - Phí quản lý 39,000,000 VNĐ /năm
A22: 14 | B22: BFT Parking maintenance | C22: Hệ thống BFT Parking mới (VETC) | D22: Parking | E22: 2026 | F22: 12 | G22: Tháng | H22: 12410000 | I22: =H22*F22 -> 148920000 | J22: =I22*0.1 -> 14892000 | K22: =SUM(I22:J22) -> 163812000 | L22: Hàng tháng | M22: 12,410,000 VNĐ - Chi phí chia sẽ doanh thu 3.65% xe vãng lai theo tháng.
A23: 15 | D23: Parking | E23: 2026 | F23: 12 | G23: Tháng | H23: 5454545 | I23: =H23*F23 -> 65454540 | J23: =I23*0.1 -> 6545454 | K23: =SUM(I23:J23) -> 71999994 | L23: Hàng tháng | M23: 5,454,545 VNĐ - Chi phí quản lý (phần mềm) theo tháng.
A24: 16 | B24: POS Skydeck maintenance | C24: Hệ thống POS Skydeck mới (CMC) | D24: Skydeck | E24: 2026 | F24: 1 | G24: 06 tháng | H24: =49000000/2 -> 24500000 | I24: =H24*F24 -> 24500000 | J24: =I24*0.1 -> 2450000 | K24: =SUM(I24:J24) -> 26950000 | L24: 12/2026 | M24: Hợp đồng bảo trì ngay sau khi hết hạn bảo hành 12 tháng
A25: 17 | B25: Internet Line | C25: Đường truyền Internet + IP tĩnh (Viettel) | D25: General | E25: 2026 | F25: 1 | G25: Năm | H25: 24000000 | I25: =H25*F25 -> 24000000 | J25: =H25*0.1 -> 2400000 | K25: =SUM(I25:J25) -> 26400000 | L25: 04/2026 | M25: Chi phí gia hạn HĐ năm 2026. Hợp đồng hết hạn ngày 01/04/2026
A26: 18 | C26: IP Public (Viettel) | D26: General | E26: 2026 | F26: 1 | G26: Năm | H26: 5454545 | I26: =H26*F26 -> 5454545 | J26: =H26*0.1 -> 545454.5 | K26: =SUM(I26:J26) -> 5999999.5 | L26: 02/2026 | M26: Phí gia hạn hợp đồng 1 năm cho năm 2026. HĐ hết hạn vào 02/2026
A27: 19 | C27: Đường truyền Internet FPT Super250 (SKYDECK) | D27: General | E27: 2026 | F27: 1 | G27: Năm | H27: =6540000/1.1 -> 5945454.5 | I27: =H27*F27 -> 5945454.5 | J27: =H27*0.1 -> 594545.45 | K27: =SUM(I27:J27) -> 6540000 | L27: 07/2026 | M27: Chi phí gia hạn HĐ năm 2025. Hợp đồng hết hạn ngày 06/07/2026.
A28: 20 | C28: IP Public (FPT) | D28: General | E28: 2026 | F28: 1 | G28: Năm | H28: 5454545 | I28: =H28*F28 -> 5454545 | J28: =H28*0.1 -> 545454.5 | K28: =SUM(I28:J28) -> 5999999.5 | L28: 11/2026 | M28: Chi phí gia hạn HĐ năm 2025. Hợp đồng hết hạn ngày 11/2026.
A29: 21 | B29: MPLS Line | C29: Kênh truyền MPLS (FPT) - 4Mbps | D29: General | E29: 2026 | F29: 1 | G29: Năm | H29: 48000000 | I29: =H29*F29 -> 48000000 | J29: =H29*0.1 -> 4800000 | K29: =SUM(I29:J29) -> 52800000 | L29: 08/2026 | M29: Chi phí gia hạn năm 2026. HĐ hết hạn vào 31/08/2026
A30: 22 | B30: Màn hình cảm ứng | C30: Màn hình Touch Screen 55 inch (3D/360 - Skydeck) | D30: Skydeck | E30: 2026 | F30: 1 | G30: Cái | H30: 60000000 | I30: =H30*F30 -> 60000000 | J30: =I30*0.1 -> 6000000 | K30: =SUM(I30:J30) -> 66000000 | L30: 08/2026 | M30: - Thay thế 1 màn hình đang xuống cấp không còn đáp ứng trong vận hành.
A31: 23 | B31: Thiết bị văn phòng | C31: HP Pro tower 280 | D31: Office | E31: 2026 | F31: 3 | G31: Cái | H31: 11363636 | I31: =H31*F31 -> 34090908 | J31: =I31*0.1 -> 3409090.8 | K31: =SUM(I31:J31) -> 37499999 | L31: 06/2026 | M31: - Nâng cấp cho máy tính CBNV
A32: 24 | C32: Màn hình Dell E2225HM (21.5 inch - VA - FHD - 100Hz-5ms) | D32: Office | E32: 2026 | F32: 7 | G32: Cái | H32: 2050000 | I32: =H32*F32 -> 14350000 | J32: =I32*0.1 -> 1435000 | K32: =SUM(I32:J32) -> 15785000 | L32: 06/2026 | M32: - Nâng cấp cho máy tính CBNV
A33: 25 | C33: Laptop Dell Latitude 3450 | D33: Office | E33: 2026 | F33: 1 | G33: Cái | H33: 25000000 | I33: =H33*F33 -> 25000000 | J33: =I33*0.1 -> 2500000 | K33: =SUM(I33:J33) -> 27500000 | L33: 06/2026 | M33: - Nâng cấp cho máy tính CBNV
A34: 26 | C34: HP Color LaserJet CP5225dn (CE742A) | D34: Office | E34: 2026 | F34: 1 | G34: Cái | H34: 30000000 | I34: =H34*F34 -> 30000000 | J34: =I34*0.1 -> 3000000 | K34: =SUM(I34:J34) -> 33000000 | L34: 06/2026 | M34: - Mua mới cho khối văn phòng
A35: 27 | C35: Máy in mã vạch HPRT HT300 | D35: Office | E35: 2026 | F35: 1 | G35: Cái | H35: 3450000 | I35: =H35*F35 -> 3450000 | J35: =I35*0.1 -> 345000 | K35: =SUM(I35:J35) -> 3795000 | L35: 06/2026 | M35: - Thay thế máy Kế toán kho
A36: 28 | C36: SSD 256GB LEXAR NS100 | D36: Office | E36: 2026 | F36: 2 | G36: Cái | H36: 700000 | I36: =H36*F36 -> 1400000 | J36: =I36*0.1 -> 140000 | K36: =SUM(I36:J36) -> 1540000 | L36: 06/2026 | M36: - Sử dụng trình chiếu cho các sự kiện của Công ty
A37: 29 | C37: Máy chiếu BenQ | D37: Office | E37: 2026 | F37: 1 | G37: Cái | H37: 35000000 | I37: =H37*F37 -> 35000000 | J37: =I37*0.1 -> 3500000 | K37: =SUM(I37:J37) -> 38500000 | L37: 02/2026
A38: 30 | C38: Màn chiếu điện 180 inch | D38: Office | E38: 2026 | F38: 1 | G38: Cái | H38: 10000000 | I38: =H38*F38 -> 10000000 | J38: =I38*0.1 -> 1000000 | K38: =SUM(I38:J38) -> 11000000 | L38: 02/2026
A39: 31 | C39: Amply, Loa + Bộ Micro không dây | D39: Office | E39: 2026 | F39: 1 | G39: Bộ | H39: 40000000 | I39: =H39*F39 -> 40000000 | J39: =I39*0.1 -> 4000000 | K39: =SUM(I39:J39) -> 44000000 | L39: 02/2026 | M39: - Sử dụng cho sự kiện tại Công ty và Team Building
A40: 32 | C40: Laptop cho Mr. Thế - HR | D40: Office | E40: 2026 | F40: 1 | G40: Cái | H40: 30100000 | I40: =H40*F40 -> 30100000 | J40: =I40*0.1 -> 3010000 | K40: =SUM(I40:J40) -> 33110000 | L40: 02/2026 | M40: - Laptop hiện tại đang yếu và thường xuyên lỗi. Cần thay thế máy cấu hình cao để thực hiện dự án AI cho HR.
A41: 33 | B41: PMG (new) | C41: Laptop Dell Latitude 3450 | D41: Office | E41: 2026 | F41: 5 | G41: Cái | H41: 25000000 | I41: =H41*F41 -> 125000000 | J41: =I41*0.1 -> 12500000 | K41: =SUM(I41:J41) -> 137500000 | L41: 01/2026 | M41: - Cấp cho PMG mới
A42: 34 | B42: New Office (7F) | C42: Màn hình tương tác SAMSUNG 86 inch | D42: Office | E42: 2026 | F42: 1 | G42: Cái | H42: 80000000 | I42: =H42*F42 -> 80000000 | J42: =I42*0.1 -> 8000000 | K42: =SUM(I42:J42) -> 88000000 | L42: 04/2026 | M42: - Sử dụng cho Văn phòng mới 7F
...

Sheet GARDEN
A1: CHI TIẾT CÁC HẠNG MỤC TRONG NGÂN SÁCH IT 2026
A2: Diễn giải | B2: số lượng dự kiến | C2: Đơn giá | D2: Thành Tiền | E2: NOTE 2026 | F2: Dự kiến hoàn thành | G2: Số Năm Phân Bổ | H2: CP PB/năm | I2: CP PB/tháng | J2: THÁNG 1 | K2: THÁNG 2 | L2: THÁNG 3 | M2: THÁNG 4 | N2: THÁNG 5 | O2: THÁNG 6 | P2: THÁNG 7 | Q2: THÁNG 8 | R2: THÁNG 9 | S2: THÁNG 10 | T2: THÁNG 11 | U2: THÁNG 12 | V2: TOTAL/năm
A3: A. TTTM The Garden | D3: =SUM(D4:D42)-D6-D16-D21 -> 3176734600 | J3: =SUM(J4:J38) -> 12351601 | K3: =SUM(K4:K38) -> 17212712 | L3: =SUM(L4:L38) -> 32004378 | M3: =SUM(M4:M38) -> 64504378 | N3: =SUM(N4:N38) -> 74779378 | O3: =SUM(O4:O38) -> 88586777 | P3: =SUM(P4:P38) -> 89420110 | Q3: =SUM(Q4:Q38) -> 89420110 | ... V3: =SUM(V4:V38) -> 692688471
V4: =SUM(J4:U4) -> 0
A5: Máy chấm công Garden + Adapter máy | B5: 2 | C5: 2600000 | D5: =+C5*B5 -> 5200000 | E5: Dự phòng | F5: Tháng 11 | G5: 1 | H5: =ROUND(+D5/G5,0) -> 5200000 | I5: =ROUND(+H5/12,0) -> 433333 | T5: =+U5 -> 433333 | U5: =+I5 -> 433333 | V5: =SUM(J5:U5) -> 866666
A6: Mua máy tính mới cho CBNV: Ms Thu thiết kế, Thu Admin, 3 nhân sự mới dự phòng, 7 màn hình PKT + 3 CRM | D6: =SUM(D7:D10) -> 100000000 | E6: Kho Senix còn máy tính, ko có màn hình | G6: 3 | J6: =SUM(J7:J10) -> 416667 | K6: =SUM(K7:K10) -> 1527778 | L6: =SUM(L7:L10) -> 1527778 | M6: =SUM(M7:M10) -> 1527778 | N6: =SUM(N7:N10) -> 1527778 | O6: =SUM(O7:O10) -> 1527778 | P6: =SUM(P7:P10) -> 1527778 | Q6: =SUM(Q7:Q10) -> 1527778 | ... U6: =SUM(U7:U10) -> 2777778
A7: Máy tính Mrs Thu Thiết kế | B7: 1 | C7: 15000000 | D7: =+C7*B7 -> 15000000 | E7: Xuất từ kho Senix | F7: Tháng 1 | G7: 3 | H7: =ROUND(+D7/G7,0) -> 5000000 | I7: =ROUND(+H7/12,0) -> 416667 | J7: =+$I7 -> 416667 | K7: =+$I7 -> 416667 | L7: =+$I7 -> 416667 | M7: =+$I7 -> 416667 | N7: =+$I7 -> 416667 | O7: =+$I7 -> 416667 | P7: =+$I7 -> 416667 | Q7: =+$I7 -> 416667 | ... U7: =+$I7 -> 416667 | V7: =SUM(J7:U7) -> 5000004
A8: Thay 01 PC cho Mrs Thu Admin | B8: 1 | C8: 15000000 | D8: =+C8*B8 -> 15000000 | E8: Xuất từ kho Senix | F8: Tháng 2 | G8: 3 | H8: =ROUND(+D8/G8,0) -> 5000000 | I8: =ROUND(+H8/12,0) -> 416667 | K8: =+$I8 -> 416667 | L8: =+$I8 -> 416667 | M8: =+$I8 -> 416667 | N8: =+$I8 -> 416667 | O8: =+$I8 -> 416667 | P8: =+$I8 -> 416667 | Q8: =+$I8 -> 416667 | R8: =+$I8 -> 416667 | ... U8: =+$I8 -> 416667 | V8: =SUM(J8:U8) -> 4583337
A9: Máy xách tay mới nhân sự mới ( 03 người ) | B9: 3 | C9: 15000000 | D9: =+C9*B9 -> 45000000 | E9: Xuất từ kho Senix | F9: Tháng 12 | G9: 3 | H9: =ROUND(+D9/G9,0) -> 15000000 | I9: =ROUND(+H9/12,0) -> 1250000 | U9: =+I9 -> 1250000 | V9: =SUM(J9:U9) -> 1250000
A10: Mua 10 màn hình máy tính 23inch phòng kế toán + CRM | B10: 10 | C10: 2500000 | D10: =+C10*B10 -> 25000000 | E10: 7 kế toán + 03 CRM | F10: Tháng 2 | G10: 3 | H10: =ROUND(+D10/G10,0) -> 8333333 | I10: =ROUND(+H10/12,0) -> 694444 | K10: =+$I10 -> 694444 | L10: =+$I10 -> 694444 | M10: =+$I10 -> 694444 | N10: =+$I10 -> 694444 | O10: =+$I10 -> 694444 | P10: =+$I10 -> 694444 | Q10: =+$I10 -> 694444 | R10: =+$I10 -> 694444 | ... U10: =+$I10 -> 694444 | V10: =SUM(J10:U10) -> 7638884
A11: Nâng cấp RAM + SSD cho người dùng văn phòng, 10 UPS cho PKT | B11: 10 | C11: =+(2000000+1500000) -> 3500000 | D11: =+C11*B11 -> 35000000 | E11: Giai đoạn 1 năm 2025 đã update RAM cho 10 người; UPS của phòng KT đã hỏng, cần đc thay để tránh mất dữ liệu khi sự cố | F11: Tháng 3 | G11: 2 | H11: =ROUND(+D11/G11,0) -> 17500000 | I11: =ROUND(+H11/12,0) -> 1458333 | L11: =+I11 -> 1458333 | M11: =+L11 -> 1458333 | N11: =+M11 -> 1458333 | O11: =+N11 -> 1458333 | P11: =+O11 -> 1458333 | Q11: =+P11 -> 1458333 | R11: =+Q11 -> 1458333 | S11: =+R11 -> 1458333 | T11: =+S11 -> 1458333 | U11: =+T11 -> 1458333 | V11: =SUM(J11:U11) -> 14583330
A12: Thay thế UPS cho các máy kế toán | B12: 10 | C12: 1500000 | E12: Các UPS cũ đã hỏng hết lên các PC của kế toán cần dc trang bị tránh mất nguồn đột ngột hỏng dữ liệu và files | F12: Tháng 5 | G12: 2 | H12: =ROUND(+D12/G12,0) -> 0 | I12: =ROUND(+H12/12,0) -> 0 | N12: =+$I12 -> 0 | O12: =+$I12 -> 0 | P12: =+$I12 -> 0 | Q12: =+$I12 -> 0 | R12: =+$I12 -> 0 | S12: =+$I12 -> 0 | T12: =+$I12 -> 0 | U12: =+$I12 -> 0 | V12: =SUM(J12:U12) -> 0
A13: Dự phòng máy in (Văn Phòng + Kiểm Phẩm) | B13: 2 | C13: 11000000 | D13: =+C13*B13 -> 22000000 | E13: Dự phòng | F13: Tháng 12 | G13: 2 | H13: =ROUND(+D13/G13,0) -> 11000000 | I13: =ROUND(+H13/12,0) -> 916667 | U13: =+I13 -> 916667 | V13: =SUM(J13:U13) -> 916667
A14: Sửa chữa, thay thế: dây mạng, cáp, chuột, pin, bàn phím… | B14: 1 | C14: 18000000 | D14: =+C14*B14 -> 18000000 | E14: Thay thế khi thực tế phát sinh | F14: Tháng 1 | G14: 1 | H14: =ROUND(+D14/G14,0) -> 18000000 | I14: =ROUND(+H14/12,0) -> 1500000 | J14: =+I14 -> 1500000 | K14: =+J14 -> 1500000 | L14: =+K14 -> 1500000 | M14: =+L14 -> 1500000 | N14: =+M14 -> 1500000 | O14: =+N14 -> 1500000 | P14: =+O14 -> 1500000 | Q14: =+P14 -> 1500000 | ... U14: =+T14 -> 1500000 | V14: =SUM(J14:U14) -> 18000000
A15: Dự phòng WIFi Garden + cung cấp WIFI cho hệ thống thu ngân bên ngoài TTTM | B15: 2 | C15: 5000000 | D15: =+C15*B15 -> 10000000 | E15: Lắp đặt bổ sung cho thu ngân phục vụ khách hàng chuyển khoản QR. Bộ phát sóng chuyển từ Senix | F15: Tháng 3 | G15: 1 | H15: =ROUND(+D15/G15,0) -> 10000000 | I15: =ROUND(+H15/12,0) -> 833333 | L15: =+I15 -> 833333 | M15: =+L15 -> 833333 | N15: =+M15 -> 833333 | O15: =+N15 -> 833333 | P15: =+O15 -> 833333 | Q15: =+P15 -> 833333 | R15: =+$I15 -> 833333 | S15: =+$I15 -> 833333 | T15: =+$I15 -> 833333 | U15: =+$I15 -> 833333 | V15: =SUM(J15:U15) -> 8333330
A16: Cước internet (FTTH CMC, FPT, WAN) | D16: =SUM(D17:D19) -> 136354200 | E16: Gia hạn hàng năm (WAN từ T6; Internet từ T5, CMC đến 4/3/27) | G16: 1 | O16: =SUM(O17:O19) -> 10833438 | P16: =SUM(P17:P19) -> 10833438 | Q16: =SUM(Q17:Q19) -> 10833438 | R16: =SUM(R17:R19) -> 10833438 | S16: =SUM(S17:S19) -> 10833438 | T16: =SUM(T17:T19) -> 10833438 | U16: =SUM(U17:U19) -> 10833438
A17: Cước WAN đ.th tổng đài T7/25-T5/26 | B17: 1 | C17: =12*1862850 -> 22354200 | D17: =+C17*B17 -> 22354200 | E17: Gia hạn hàng năm | F17: Tháng 6 | G17: 1 | H17: =ROUND(+D17/G17,0) -> 22354200 | I17: =ROUND(+H17/12,0) -> 1862850 | O17: =+I17 -> 1862850 | P17: =+O17 -> 1862850 | Q17: =+P17 -> 1862850 | R17: =+Q17 -> 1862850 | S17: =+R17 -> 1862850 | T17: =+S17 -> 1862850 | U17: =+T17 -> 1862850 | V17: =SUM(J17:U17) -> 13039950
A18: CMC/Cước FTTH (05/10/25- 04/03/27) | B18: 1 | C18: 21600000 | D18: =+C18*B18 -> 21600000 | E18: Đã gia hạn từ 2025 | F18: Tháng 1 | G18: =17/12 -> 1.4166667 | H18: =ROUND(+D18/G18,0) -> 15247059 | I18: =ROUND(+H18/12,0) -> 1270588 | J18: =+I18 -> 1270588 | K18: =+J18 -> 1270588 | L18: =+K18 -> 1270588 | M18: =+L18 -> 1270588 | N18: =+M18 -> 1270588 | O18: =+N18 -> 1270588 | P18: =+O18 -> 1270588 | Q18: =+P18 -> 1270588 | ... U18: =+T18 -> 1270588
A19: FPT/Cước thuê kênh internet 20/4/25-19/5/26 | B19: 1 | C19: 92400000 | D19: =+C19*B19 -> 92400000 | E19: Gia hạn hàng năm | F19: Tháng 5 | G19: 1 | H19: =ROUND(+D19/G19,0) -> 92400000 | I19: =ROUND(+H19/12,0) -> 7700000 | N19: =+I19 -> 7700000 | O19: =+N19 -> 7700000 | P19: =+O19 -> 7700000 | Q19: =+P19 -> 7700000 | R19: =+Q19 -> 7700000 | S19: =+R19 -> 7700000 | T19: =+S19 -> 7700000 | U19: =+T19 -> 7700000 | V19: =SUM(J19:U19) -> 61600000
A20: CP phần mềm diệt Virus (License Symantec) | B20: 1 | C20: 30000000 | D20: =+C20*B20 -> 30000000 | E20: Gia hạn hàng năm | F20: Tháng 5 | G20: 1 | H20: =ROUND(+D20/G20,0) -> 30000000 | I20: =ROUND(+H20/12,0) -> 2500000 | N20: =+$I20 -> 2500000 | O20: =+$I20 -> 2500000 | P20: =+$I20 -> 2500000 | Q20: =+$I20 -> 2500000 | R20: =+$I20 -> 2500000 | S20: =+$I20 -> 2500000 | T20: =+$I20 -> 2500000 | U20: =+$I20 -> 2500000 | V20: =SUM(J20:U20) -> 20000000
A21: Mua 01 bộ Zoom meetup + pc mini + mic đa hướng (Phục vụ họp trực tuyến); gia hạn zoom/tên miền | D21: =SUM(D22:D24) -> 40950000 | E21: =+A21 -> Mua 01 bộ Zoom meetup + pc mini + mic đa hướng (Phục vụ họp trực tuyến); gia hạn zoom/tên miền | J21: =SUM(J22:J24) -> 2531173 | K21: =SUM(K22:K24) -> 2531173 | L21: =SUM(L22:L24) -> 2531173 | M21: =SUM(M22:M24) -> 2531173 | N21: =SUM(N22:N24) -> 2568673 | O21: =SUM(O22:O24) -> 2568673 | P21: =SUM(P22:P24) -> 2568673 | Q21: =SUM(Q22:Q24) -> 2568673 | ... U21: =SUM(U22:U24) -> 2363347
A22: Mua 01 bộ Zoom meetup + pc mini + mic đa hướng (Phục vụ họp trực tuyến) | B22: 1 | C22: =17000000+13000000 -> 30000000 | D22: =+C22*B22 -> 30000000 | E22: Mua mới | F22: Tháng 1 | G22: 2 | H22: =ROUND(+D22/G22,0) -> 15000000 | I22: =ROUND(+H22/12,0) -> 1250000 | J22: =+I22 -> 1250000 | K22: =+J22 -> 1250000 | L22: =+K22 -> 1250000 | M22: =+L22 -> 1250000 | N22: =+M22 -> 1250000 | O22: =+N22 -> 1250000 | P22: =+O22 -> 1250000 | Q22: =+P22 -> 1250000 | ... U22: =+T22 -> 1250000 | V22: =SUM(J22:U22) -> 15000000
A23: CP gia hạn Zoom | B23: 3 | C23: 3650000 | D23: =+C23*B23 -> 10950000 | E23: Gia hạn hàng năm | F23: Tháng 5 | G23: 1 | H23: =ROUND(+D23/G23,0) -> 10950000 | I23: =ROUND(+H23/12,0) -> 912500 | J23: =+'[2]pbcp 2026. est 10 BMTL + All'!O317 -> 875000 | K23: =+'[2]pbcp 2026. est 10 BMTL + All'!P317 -> 875000 | L23: =+'[2]pbcp 2026. est 10 BMTL + All'!Q317 -> 875000 | M23: =+'[2]pbcp 2026. est 10 BMTL + All'!R317 -> 875000 | N23: =+I23 -> 912500 | O23: =+N23 -> 912500 | P23: =+O23 -> 912500 | Q23: =+P23 -> 912500 | R23: =+Q23 -> 912500 | S23: =+R23 -> 912500 | T23: =+S23 -> 912500 | U23: =+T23 -> 912500 | V23: =SUM(J23:U23) -> 10800000
A24: CP gia hạn tên miền | B24: 1 | C24: =0*6000000 -> 0 | D24: =+C24*B24 -> 0 | E24: Đã gia hạn 5 năm từ 2024 | F24: Tháng 1 | G24: 1 | H24: =ROUND(+D24/G24,0) -> 0 | I24: =ROUND(+H24/12,0) -> 0 | J24: =+'[2]pbcp 2026. est 10 BMTL + All'!O315+'[2]pbcp 2026. est 10 BMTL + All'!O316 -> 406173 | K24: =+'[2]pbcp 2026. est 10 BMTL + All'!P315+'[2]pbcp 2026. est 10 BMTL + All'!P316 -> 406173 | L24: =+'[2]pbcp 2026. est 10 BMTL + All'!Q315+'[2]pbcp 2026. est 10 BMTL + All'!Q316 -> 406173 | M24: =+'[2]pbcp 2026. est 10 BMTL + All'!R315+'[2]pbcp 2026. est 10 BMTL + All'!R316 -> 406173 | N24: =+'[2]pbcp 2026. est 10 BMTL + All'!S315+'[2]pbcp 2026. est 10 BMTL + All'!S316 -> 406173 | O24: =+'[2]pbcp 2026. est 10 BMTL + All'!T315+'[2]pbcp 2026. est 10 BMTL + All'!T316 -> 406173 | P24: =+'[2]pbcp 2026. est 10 BMTL + All'!U315+'[2]pbcp 2026. est 10 BMTL + All'!U316 -> 406173 | Q24: =+'[2]pbcp 2026. est 10 BMTL + All'!V315+'[2]pbcp 2026. est 10 BMTL + All'!V316 -> 406173 | ... U24: =+'[2]pbcp 2026. est 10 BMTL + All'!Z315+'[2]pbcp 2026. est 10 BMTL + All'!Z316 -> 200847 | V24: =SUM(J24:U24) -> 4463418
A25: HỆ THỐNG MÁY CHỦ | V25: =SUM(J25:U25) -> 0
A26: Thiết bị tường lửa firewall fortinet (để chia tải cho server đang quá tải) | B26: 1 | C26: 95000000 | D26: =+C26*B26 -> 95000000 | E26: Hiện tại đang có 02 Firewall 100D và 100E dùng cho toàn hệ thống. Thiết bị đã đưa vào sử dụng được trên 7 năm vì thế năm nay thay thế 01 cái | F26: Tháng 2 | G26: 3 | H26: =ROUND(+D26/G26,0) -> 31666667 | I26: =ROUND(+H26/12,0) -> 2638889 | K26: =+$I26 -> 2638889 | L26: =+$I26 -> 2638889 | M26: =+$I26 -> 2638889 | N26: =+$I26 -> 2638889 | O26: =+$I26 -> 2638889 | P26: =+$I26 -> 2638889 | Q26: =+$I26 -> 2638889 | R26: =+$I26 -> 2638889 | ... U26: =+$I26 -> 2638889 | V26: =SUM(J26:U26) -> 29027779
A27: License cho fire wall 100E | B27: 1 | C27: 34000000 | D27: =+C27*B27 -> 34000000 | E27: Bản quyền hết hạn cần dc gia hạn | F27: Tháng 1 | G27: 1 | H27: =ROUND(+D27/G27,0) -> 34000000 | I27: =ROUND(+H27/12,0) -> 2833333 | J27: =+I27 -> 2833333 | K27: =+J27 -> 2833333 | L27: =+K27 -> 2833333 | M27: =+L27 -> 2833333 | N27: =+M27 -> 2833333 | O27: =+N27 -> 2833333 | P27: =+O27 -> 2833333 | Q27: =+P27 -> 2833333 | ... U27: =+T27 -> 2833333 | V27: =SUM(J27:U27) -> 33999996
